<?xml version="1.0" ?>
<!-- Generated using onshape-to-robot -->
<!-- Onshape https://cad.onshape.com/documents/5c7655f7a10be258b255653e/w/9b7cf7340f5f742e2d847e84/e/661a4991913bb205efad3807 -->
<robot name="so101_yaw">
  <!-- Link base_so101_v2 -->
  <link name="base_so101_v2">
    <inertial>
      <origin xyz="-0.00654505 -0.0274557 0.034086" rpy="0 0 0"/>
      <mass value="0.151"/>
      <inertia ixx="0.00012688" ixy="-5.94796e-07" ixz="2.98671e-06" iyy="0.000135694" iyz="-6.97256e-08" izz="0.000132445"/>
    </inertial>
    <!-- Part sts3215 -->
    <visual>
      <origin xyz="0.00489886 -0.0272511 0.0461" rpy="-1.89638e-16 -7.4744e-16 -3.26128e-15"/>
      <geometry>
        <mesh filename="package://assets/sts3215.stl"/>
      </geometry>
      <material name="sts3215_material">
        <color rgba="0.235294 0.235294 0.235294 1"/>
      </material>
    </visual>
    <collision>
      <origin xyz="0.00489886 -0.0272511 0.0461" rpy="-1.89638e-16 -7.4744e-16 -3.26128e-15"/>
      <geometry>
        <mesh filename="package://assets/sts3215.stl"/>
      </geometry>
    </collision>
    <!-- Part base_motor_holder_so101_v1 -->
    <visual>
      <origin xyz="-0.0275011 -0.0276006 1.33995e-16" rpy="1.5708 7.86155e-17 1.5708"/>
      <geometry>
        <mesh filename="package://assets/base_motor_holder_so101_v1.stl"/>
      </geometry>
      <material name="base_motor_holder_so101_v1_material">
        <color rgba="0.235294 0.235294 0.235294 1"/>
      </material>
    </visual>
    <collision>
      <origin xyz="-0.0275011 -0.0276006 1.33995e-16" rpy="1.5708 7.86155e-17 1.5708"/>
      <geometry>
        <mesh filename="package://assets/base_motor_holder_so101_v1.stl"/>
      </geometry>
    </collision>
    <!-- Part base_so101_v2 -->
    <visual>
      <origin xyz="-0.0275011 -0.0275011 7.15369e-17" rpy="1.5708 7.86155e-17 1.5708"/>
      <geometry>
        <mesh filename="package://assets/base_so101_v2.stl"/>
      </geometry>
      <material name="base_so101_v2_material">
        <color rgba="0.235294 0.235294 0.235294 1"/>
      </material>
    </visual>
    <collision>
      <origin xyz="-0.0275011 -0.0275011 7.15369e-17" rpy="1.5708 7.86155e-17 1.5708"/>
      <geometry>
        <mesh filename="package://assets/base_so101_v2.stl"/>
      </geometry>
    </collision>
  </link>
  <!-- Link rotation_pitch_so101_v1 -->
  <link name="rotation_pitch_so101_v1">
    <inertial>
      <origin xyz="0.0309888 5.41298e-05 -0.0231919" rpy="0 0 0"/>
      <mass value="0.102"/>
      <inertia ixx="9.02965e-05" ixy="7.51737e-08" ixz="1.45988e-06" iyy="8.80808e-05" iyz="-1.36387e-07" izz="2.50511e-05"/>
    </inertial>
    <!-- Part motor_holder_so101_base_v1 -->
    <visual>
      <origin xyz="0.0678 0.0002 0.0158499" rpy="-1.5708 -1.5708 0"/>
      <geometry>
        <mesh filename="package://assets/motor_holder_so101_base_v1.stl"/>
      </geometry>
      <material name="motor_holder_so101_base_v1_material">
        <color rgba="0.235294 0.235294 0.235294 1"/>
      </material>
    </visual>
    <collision>
      <origin xyz="0.0678 0.0002 0.0158499" rpy="-1.5708 -1.5708 0"/>
      <geometry>
        <mesh filename="package://assets/motor_holder_so101_base_v1.stl"/>
      </geometry>
    </collision>
    <!-- Part rotation_pitch_so101_v1 -->
    <visual>
      <origin xyz="-0.012 1.73472e-17 0.0464" rpy="-1.5708 -3.89251e-16 3.14159"/>
      <geometry>
        <mesh filename="package://assets/rotation_pitch_so101_v1.stl"/>
      </geometry>
      <material name="rotation_pitch_so101_v1_material">
        <color rgba="0.235294 0.235294 0.235294 1"/>
      </material>
    </visual>
    <collision>
      <origin xyz="-0.012 1.73472e-17 0.0464" rpy="-1.5708 -3.89251e-16 3.14159"/>
      <geometry>
        <mesh filename="package://assets/rotation_pitch_so101_v1.stl"/>
      </geometry>
    </collision>
    <!-- Part sts3215_2 -->
    <visual>
      <origin xyz="0.0306 -0.0004 -0.0417" rpy="-1.5708 1.5708 0"/>
      <geometry>
        <mesh filename="package://assets/sts3215.stl"/>
      </geometry>
      <material name="sts3215_2_material">
        <color rgba="0.235294 0.235294 0.235294 1"/>
      </material>
    </visual>
    <collision>
      <origin xyz="0.0306 -0.0004 -0.0417" rpy="-1.5708 1.5708 0"/>
      <geometry>
        <mesh filename="package://assets/sts3215.stl"/>
      </geometry>
    </collision>
  </link>
  <!-- Link upper_arm_so101_v1 -->
  <link name="upper_arm_so101_v1">
    <inertial>
      <origin xyz="0.0875462 0.00769199 0.0183923" rpy="0 0 0"/>
      <mass value="0.106"/>
      <inertia ixx="4.29162e-05" ixy="-2.05885e-05" ixz="8.97322e-08" iyy="0.000159358" iyz="-1.79716e-08" izz="0.00015251"/>
    </inertial>
    <!-- Part sts3215_3 -->
    <visual>
      <origin xyz="0.11257 0.0155 0.0187" rpy="-3.14159 -1.11022e-16 1.5708"/>
      <geometry>
        <mesh filename="package://assets/sts3215.stl"/>
      </geometry>
      <material name="sts3215_3_material">
        <color rgba="0.235294 0.235294 0.235294 1"/>
      </material>
    </visual>
    <collision>
      <origin xyz="0.11257 0.0155 0.0187" rpy="-3.14159 -1.11022e-16 1.5708"/>
      <geometry>
        <mesh filename="package://assets/sts3215.stl"/>
      </geometry>
    </collision>
    <!-- Part upper_arm_so101_v1 -->
    <visual>
      <origin xyz="0.065085 -0.012 0.0182" rpy="3.14159 -1.11022e-16 -3.14159"/>
      <geometry>
        <mesh filename="package://assets/upper_arm_so101_v1.stl"/>
      </geometry>
      <material name="upper_arm_so101_v1_material">
        <color rgba="0.235294 0.235294 0.235294 1"/>
      </material>
    </visual>
    <collision>
      <origin xyz="0.065085 -0.012 0.0182" rpy="3.14159 -1.11022e-16 -3.14159"/>
      <geometry>
        <mesh filename="package://assets/upper_arm_so101_v1.stl"/>
      </geometry>
    </collision>
  </link>
  <!-- Link under_arm_so101_v1 -->
  <link name="under_arm_so101_v1">
    <inertial>
      <origin xyz="0.0953096 -0.00302426 0.0182473" rpy="0 0 0"/>
      <mass value="0.11"/>
      <inertia ixx="3.24107e-05" ixy="8.01383e-06" ixz="-1.40404e-06" iyy="0.000176111" iyz="4.66378e-08" izz="0.000159352"/>
    </inertial>
    <!-- Part under_arm_so101_v1 -->
    <visual>
      <origin xyz="0.0648499 0.032 0.0182" rpy="-3.14159 -8.3322e-16 3.14159"/>
      <geometry>
        <mesh filename="package://assets/under_arm_so101_v1.stl"/>
      </geometry>
      <material name="under_arm_so101_v1_material">
        <color rgba="0.235294 0.235294 0.235294 1"/>
      </material>
    </visual>
    <collision>
      <origin xyz="0.0648499 0.032 0.0182" rpy="-3.14159 -8.3322e-16 3.14159"/>
      <geometry>
        <mesh filename="package://assets/under_arm_so101_v1.stl"/>
      </geometry>
    </collision>
    <!-- Part sts3215_4 -->
    <visual>
      <origin xyz="0.1224 -0.0052 0.0187" rpy="3.14159 1.38833e-15 -7.17499e-14"/>
      <geometry>
        <mesh filename="package://assets/sts3215.stl"/>
      </geometry>
      <material name="sts3215_4_material">
        <color rgba="0.235294 0.235294 0.235294 1"/>
      </material>
    </visual>
    <collision>
      <origin xyz="0.1224 -0.0052 0.0187" rpy="3.14159 1.38833e-15 -7.17499e-14"/>
      <geometry>
        <mesh filename="package://assets/sts3215.stl"/>
      </geometry>
    </collision>
    <!-- Part motor_holder_so101_wrist_v1 -->
    <visual>
      <origin xyz="0.0648499 0.032 0.018" rpy="-3.14159 -1.15366e-15 3.14159"/>
      <geometry>
        <mesh filename="package://assets/motor_holder_so101_wrist_v1.stl"/>
      </geometry>
      <material name="motor_holder_so101_wrist_v1_material">
        <color rgba="0.235294 0.235294 0.235294 1"/>
      </material>
    </visual>
    <collision>
      <origin xyz="0.0648499 0.032 0.018" rpy="-3.14159 -1.15366e-15 3.14159"/>
      <geometry>
        <mesh filename="package://assets/motor_holder_so101_wrist_v1.stl"/>
      </geometry>
    </collision>
  </link>
  <!-- Link wrist_yaw_back_v2 -->
  <link name="wrist_yaw_back_v2">
    <inertial>
      <origin xyz="0.0170191 -0.00963991 0.0183001" rpy="0 0 0"/>
      <mass value="0.02"/>
      <inertia ixx="8.43061e-06" ixy="1.40805e-06" ixz="3.45132e-11" iyy="6.67798e-06" iyz="-5.27682e-11" izz="6.60703e-06"/>
    </inertial>
    <!-- Part wrist_yaw_back_v2 -->
    <visual>
      <origin xyz="-8.32667e-17 2.77556e-17 0.0183" rpy="-1.5708 2.71835e-16 -3.14159"/>
      <geometry>
        <mesh filename="package://assets/wrist_yaw_back_v2.stl"/>
      </geometry>
      <material name="wrist_yaw_back_v2_material">
        <color rgba="0.756863 0.180392 0.121569 1"/>
      </material>
    </visual>
    <collision>
      <origin xyz="-8.32667e-17 2.77556e-17 0.0183" rpy="-1.5708 2.71835e-16 -3.14159"/>
      <geometry>
        <mesh filename="package://assets/wrist_yaw_back_v2.stl"/>
      </geometry>
    </collision>
  </link>
  <!-- Link wrist_yaw_front_v2 -->
  <link name="wrist_yaw_front_v2">
    <inertial>
      <origin xyz="-0.0288469 3.2095e-05 0.00318547" rpy="0 0 0"/>
      <mass value="0.14"/>
      <inertia ixx="9.23015e-05" ixy="4.59386e-08" ixz="3.54146e-05" iyy="0.000129134" iyz="2.4354e-08" izz="5.50963e-05"/>
    </inertial>
    <!-- Part sts3215_5 -->
    <visual>
      <origin xyz="-0.0125 0 -0.0187" rpy="-9.1624e-32 1.59776e-24 2.1032e-30"/>
      <geometry>
        <mesh filename="package://assets/sts3215.stl"/>
      </geometry>
      <material name="sts3215_5_material">
        <color rgba="0.235294 0.235294 0.235294 1"/>
      </material>
    </visual>
    <collision>
      <origin xyz="-0.0125 0 -0.0187" rpy="-9.1624e-32 1.59776e-24 2.1032e-30"/>
      <geometry>
        <mesh filename="package://assets/sts3215.stl"/>
      </geometry>
    </collision>
    <!-- Part sts3215_6 -->
    <visual>
      <origin xyz="-0.0428 3.08781e-16 0.025043" rpy="8.70125e-30 -1.5708 0"/>
      <geometry>
        <mesh filename="package://assets/sts3215.stl"/>
      </geometry>
      <material name="sts3215_6_material">
        <color rgba="0.235294 0.235294 0.235294 1"/>
      </material>
    </visual>
    <collision>
      <origin xyz="-0.0428 3.08781e-16 0.025043" rpy="8.70125e-30 -1.5708 0"/>
      <geometry>
        <mesh filename="package://assets/sts3215.stl"/>
      </geometry>
    </collision>
    <!-- Part wrist_yaw_front_v2 -->
    <visual>
      <origin xyz="-0.0283 1.17961e-16 0.0037965" rpy="-3.14159 1.28026e-16 -3.14159"/>
      <geometry>
        <mesh filename="package://assets/wrist_yaw_front_v2.stl"/>
      </geometry>
      <material name="wrist_yaw_front_v2_material">
        <color rgba="0.756863 0.180392 0.121569 1"/>
      </material>
    </visual>
    <collision>
      <origin xyz="-0.0283 1.17961e-16 0.0037965" rpy="-3.14159 1.28026e-16 -3.14159"/>
      <geometry>
        <mesh filename="package://assets/wrist_yaw_front_v2.stl"/>
      </geometry>
    </collision>
  </link>
  <!-- Link gripper_body -->
  <link name="gripper_body">
    <inertial>
      <origin xyz="-0.000636413 -0.00019243 -0.02101" rpy="0 0 0"/>
      <mass value="0.086"/>
      <inertia ixx="1.74109e-05" ixy="-2.64933e-07" ixz="-4.56581e-08" iyy="3.13894e-05" iyz="-1.1459e-07" izz="3.52206e-05"/>
    </inertial>
    <!-- Part wrist_roll_follower_so101_v1 -->
    <visual>
      <origin xyz="-3.27883e-07 0.000218214 0.000949706" rpy="3.14159 8.40848e-16 -3.14009"/>
      <geometry>
        <mesh filename="package://assets/wrist_roll_follower_so101_v1.stl"/>
      </geometry>
      <material name="wrist_roll_follower_so101_v1_material">
        <color rgba="0.964706 0.964706 0.952941 1"/>
      </material>
    </visual>
    <collision>
      <origin xyz="-3.27883e-07 0.000218214 0.000949706" rpy="3.14159 8.40848e-16 -3.14009"/>
      <geometry>
        <mesh filename="package://assets/wrist_roll_follower_so101_v1.stl"/>
      </geometry>
    </collision>
    <!-- Part sts3215_7 -->
    <visual>
      <origin xyz="-0.00770014 8.84301e-05 -0.0234" rpy="-1.5708 8.40848e-16 -3.14009"/>
      <geometry>
        <mesh filename="package://assets/sts3215.stl"/>
      </geometry>
      <material name="sts3215_7_material">
        <color rgba="0.235294 0.235294 0.235294 1"/>
      </material>
    </visual>
    <collision>
      <origin xyz="-0.00770014 8.84301e-05 -0.0234" rpy="-1.5708 8.40848e-16 -3.14009"/>
      <geometry>
        <mesh filename="package://assets/sts3215.stl"/>
      </geometry>
    </collision>
  </link>
  <!-- Link moving_jaw_so101_v1 -->
  <link name="moving_jaw_so101_v1">
    <inertial>
      <origin xyz="-0.000643301 -0.0295336 0.0192755" rpy="0 0 0"/>
      <mass value="0.013"/>
      <inertia ixx="7.16516e-06" ixy="-3.48625e-07" ixz="-6.44988e-09" iyy="2.04814e-06" iyz="-1.19105e-07" izz="5.72799e-06"/>
    </inertial>
    <!-- Part moving_jaw_so101_v1 -->
    <visual>
      <origin xyz="0.000944371 0.000490203 0.0189" rpy="1.26318e-15 2.09969e-14 -0.000423662"/>
      <geometry>
        <mesh filename="package://assets/moving_jaw_so101_v1.stl"/>
      </geometry>
      <material name="moving_jaw_so101_v1_material">
        <color rgba="0.964706 0.964706 0.952941 1"/>
      </material>
    </visual>
    <collision>
      <origin xyz="0.000944371 0.000490203 0.0189" rpy="1.26318e-15 2.09969e-14 -0.000423662"/>
      <geometry>
        <mesh filename="package://assets/moving_jaw_so101_v1.stl"/>
      </geometry>
    </collision>
  </link>
  <!-- Joint from gripper_body to moving_jaw_so101_v1 -->
  <joint name="joint7" type="revolute">
    <origin xyz="-0.020172 -0.0186303 -0.0234" rpy="1.5708 8.40848e-16 -3.14009"/>
    <parent link="gripper_body"/>
    <child link="moving_jaw_so101_v1"/>
    <axis xyz="0 0 1"/>
    <limit effort="10" velocity="10" lower="-0.174109" upper="1.74575"/>
  </joint>
  <!-- Link camera_mount -->
  <link name="camera_mount">
    <inertial>
      <origin xyz="-0.0224746 -0.00102293 -0.0255423" rpy="0 0 0"/>
      <mass value="0.012"/>
      <inertia ixx="5.52533e-06" ixy="9.51953e-08" ixz="-1.32316e-06" iyy="5.31978e-06" iyz="1.20372e-07" izz="2.25715e-06"/>
    </inertial>
    <!-- Part camera_mount -->
    <visual>
      <origin xyz="0.00815 -0.0181 -2.1684e-18" rpy="-1.5708 -1.5708 0"/>
      <geometry>
        <mesh filename="package://assets/camera_mount.stl"/>
      </geometry>
      <material name="camera_mount_material">
        <color rgba="0.235294 0.235294 0.235294 1"/>
      </material>
    </visual>
    <collision>
      <origin xyz="0.00815 -0.0181 -2.1684e-18" rpy="-1.5708 -1.5708 0"/>
      <geometry>
        <mesh filename="package://assets/camera_mount.stl"/>
      </geometry>
    </collision>
  </link>
  <!-- Link camera_body -->
  <link name="camera_body">
    <inertial>
      <origin xyz="0 0 0" rpy="0 0 0"/>
      <mass value="1e-09"/>
      <inertia ixx="1e-09" ixy="0" ixz="0" iyy="1e-09" iyz="0" izz="1e-09"/>
    </inertial>
    <!-- Part camera_uvc_25x32 -->
    <visual>
      <origin xyz="0 -0.0495931 -0.000795328" rpy="1.5708 -7.23838e-20 1.5708"/>
      <geometry>
        <mesh filename="package://assets/camera_uvc_25x32.stl"/>
      </geometry>
      <material name="camera_uvc_25x32_material">
        <color rgba="0.235294 0.235294 0.235294 1"/>
      </material>
    </visual>
    <collision>
      <origin xyz="0 -0.0495931 -0.000795328" rpy="1.5708 -7.23838e-20 1.5708"/>
      <geometry>
        <mesh filename="package://assets/camera_uvc_25x32.stl"/>
      </geometry>
    </collision>
  </link>
  <!-- Frame camera (dummy link + fixed joint) -->
  <link name="camera">
    <origin xyz="0 0 0" rpy="0 -0 0"/>
    <inertial>
      <origin xyz="0 0 0" rpy="0 0 0"/>
      <mass value="1e-9"/>
      <inertia ixx="0" ixy="0" ixz="0" iyy="0" iyz="0" izz="0"/>
    </inertial>
  </link>
  <joint name="camera_frame" type="fixed">
    <origin xyz="0.0134 0.000203456 -0.000397664" rpy="7.23838e-20 -2.65658e-17 1.24493e-19"/>
    <parent link="camera_body"/>
    <child link="camera"/>
    <axis xyz="0 0 0"/>
  </joint>
  <!-- Joint from camera_mount to camera_body -->
  <joint name="camera" type="fixed">
    <origin xyz="-0.0299654 -0.0006 -0.0493488" rpy="3.14159 -0.436332 5.4113e-20"/>
    <parent link="camera_mount"/>
    <child link="camera_body"/>
    <axis xyz="0 0 1"/>
    <limit effort="10" velocity="10"/>
  </joint>
  <!-- Joint from gripper_body to camera_mount -->
  <joint name="camera_mount" type="fixed">
    <origin xyz="-0.00306393 -0.0240046 -0.0234002" rpy="-1.5723 1.5708 0"/>
    <parent link="gripper_body"/>
    <child link="camera_mount"/>
    <axis xyz="0 0 1"/>
    <limit effort="10" velocity="10"/>
  </joint>
  <!-- Link gripper_finger -->
  <link name="gripper_finger">
    <inertial>
      <origin xyz="0.0141183 3.81789e-08 -0.0214088" rpy="0 0 0"/>
      <mass value="0.031"/>
      <inertia ixx="9.74177e-06" ixy="4.91362e-12" ixz="1.93091e-06" iyy="9.76828e-06" iyz="7.01388e-12" izz="2.30933e-06"/>
    </inertial>
    <!-- Part wrist_roll_follower_so101_v1_2 -->
    <visual>
      <origin xyz="0.0352 -4.66814e-14 0.038" rpy="-3.14159 6.05824e-16 3.64596e-16"/>
      <geometry>
        <mesh filename="package://assets/wrist_roll_follower_so101_v1__2.stl"/>
      </geometry>
      <material name="wrist_roll_follower_so101_v1_2_material">
        <color rgba="0.964706 0.964706 0.952941 1"/>
      </material>
    </visual>
    <collision>
      <origin xyz="0.0352 -4.66814e-14 0.038" rpy="-3.14159 6.05824e-16 3.64596e-16"/>
      <geometry>
        <mesh filename="package://assets/wrist_roll_follower_so101_v1__2.stl"/>
      </geometry>
    </collision>
  </link>
  <!-- Joint from gripper_body to gripper_finger -->
  <joint name="joint8" type="fixed">
    <origin xyz="0.0351996 0.000271105 -0.0370503" rpy="-1.0267e-14 8.40848e-16 -3.14009"/>
    <parent link="gripper_body"/>
    <child link="gripper_finger"/>
    <axis xyz="0 0 1"/>
    <limit effort="10" velocity="10"/>
  </joint>
  <!-- Joint from wrist_yaw_front_v2 to gripper_body -->
  <joint name="joint6" type="revolute">
    <origin xyz="-0.0615 3.05311e-16 0.037543" rpy="-3.14159 -1.5708 0"/>
    <parent link="wrist_yaw_front_v2"/>
    <child link="gripper_body"/>
    <axis xyz="0 0 1"/>
    <limit effort="10" velocity="10" lower="-2.96856" upper="2.86084"/>
  </joint>
  <!-- Joint from wrist_yaw_back_v2 to wrist_yaw_front_v2 -->
  <joint name="joint5" type="revolute">
    <origin xyz="0.029 -0.0359 0.0183" rpy="1.5708 4.20225e-14 -3.14159"/>
    <parent link="wrist_yaw_back_v2"/>
    <child link="wrist_yaw_front_v2"/>
    <axis xyz="0 0 1"/>
    <limit effort="10" velocity="10" lower="-1.53589" upper="1.53589"/>
  </joint>
  <!-- Joint from under_arm_so101_v1 to wrist_yaw_back_v2 -->
  <joint name="joint4" type="revolute">
    <origin xyz="0.1349 -0.0052 7.84095e-16" rpy="-1.01607e-15 1.38833e-15 -7.17499e-14"/>
    <parent link="under_arm_so101_v1"/>
    <child link="wrist_yaw_back_v2"/>
    <axis xyz="0 0 1"/>
    <limit effort="10" velocity="10" lower="-1.46608" upper="1.64061"/>
  </joint>
  <!-- Joint from upper_arm_so101_v1 to under_arm_so101_v1 -->
  <joint name="joint3" type="revolute">
    <origin xyz="0.11257 0.028 -1.31839e-16" rpy="8.52564e-24 -1.11022e-16 1.5708"/>
    <parent link="upper_arm_so101_v1"/>
    <child link="under_arm_so101_v1"/>
    <axis xyz="0 0 1"/>
    <limit effort="10" velocity="10" lower="-1.68948" upper="1.5708"/>
  </joint>
  <!-- Joint from rotation_pitch_so101_v1 to upper_arm_so101_v1 -->
  <joint name="joint2" type="revolute">
    <origin xyz="0.0306 0.0183 -0.0542" rpy="1.5708 1.5708 0"/>
    <parent link="rotation_pitch_so101_v1"/>
    <child link="upper_arm_so101_v1"/>
    <axis xyz="0 0 1"/>
    <limit effort="10" velocity="10" lower="-1.74533" upper="1.74533"/>
  </joint>
  <!-- Joint from base_so101_v2 to rotation_pitch_so101_v1 -->
  <joint name="joint1" type="revolute">
    <origin xyz="0.0173989 -0.0272511 0.0648" rpy="3.14159 -7.4744e-16 -3.26128e-15"/>
    <parent link="base_so101_v2"/>
    <child link="rotation_pitch_so101_v1"/>
    <axis xyz="0 0 1"/>
    <limit effort="10" velocity="10" lower="-1.91986" upper="1.91986"/>
  </joint>
</robot>
